<?xml version="1.0"?>
<robot name="robotblack_wheel" xmlns:xacro="http://ros.org/wiki/xacro">

    <!-- Include -->
    <xacro:include filename="$(find robotblack_description)/urdf/robotblack_property.xacro" />
    
    <!-- marcro wheel -->
    <xacro:macro name="wheel" params="name trans rot parent mass">
        <link name="${name}_wheel">
            <xacro:cylinder_inertial mass="${mass}" radius="0.1" length="0.02">
                <origin rpy="${-pi/2} 0 0"/>
            </xacro:cylinder_inertial>
            <visual>
                <origin rpy="${-pi/2} 0 0"/>
                <geometry>
                    <cylinder radius="0.1" length="0.02"/>
                </geometry>
                <xacro:insert_block name="material_yellow" />
            </visual>
            <collision>
                <origin rpy="${-pi/2} 0 0"/>
                <geometry>
                    <cylinder radius="0.1" length="0.02"/>
                </geometry>
            </collision>
            
        </link>

        <joint name="${name}_joint_wheel" type="continuous">
            <origin xyz="${trans}" rpy="${rot}"/>
            <parent link="${parent}"/>
            <child link="${name}_wheel"/>
            <axis rpy="0 0 0" xyz="0 1 0"/>
            <limit effort="100" velocity="100"/>
            <joint_properties damping="1.0" friction="1.0" />
        </joint>

        <gazebo reference="${name}_wheel">
            <material>Gazebo/Yellow</material>
        </gazebo>

        <transmission name="{name}_wheel">
            <type>transmission_interface/SimpleTransmission</type>
            <joint name="${name}_joint_wheel">
            <hardwareInterface>hardware_interface/EffortJointInterface</hardwareInterface>
            </joint>
            <actuator name="${name}_motor">
            <hardwareInterface>hardware_interface/EffortJointInterface</hardwareInterface>
            <mechanicalReduction>1</mechanicalReduction>
            </actuator>
        </transmission>

    </xacro:macro>
    
    <!-- macro caster wheel -->
    <xacro:macro name="wheel_caster" params="name position">
        <visual name = "${name}_caster_visual">
            <origin  xyz="${position}"/>
            <geometry>
                <sphere radius="0.05"/>
            </geometry>
            <xacro:insert_block name="material_black" />
        </visual>
        <collision name ="${name}_caster_collision">
            <origin  xyz="${position}"/>
                <geometry>
                    <sphere radius="0.05"/>
                </geometry>
            <surface>
                <friction>
                    <ode>
                        <mu>0</mu>
                        <mu2>0</mu2>
                        <slip1>1.0</slip1>
                        <slip2>1.0</slip2>
                    </ode>
                </friction>
            </surface>
        </collision>
    </xacro:macro>

</robot>